<?xml version="1.0"?>
<robot name="simple_robot">
  <link name="base_link">
    <visual>
      <geometry>
        <box size="0.1 0.1 0.1"/>
      </geometry>
    </visual>
  </link>

  <joint name="shoulder" type="revolute">
    <parent link="base_link"/>
    <child link="upper_arm"/>
    <origin rpy="0 0 0" xyz="0 0 0.05"/>
    <axis xyz="0 1 0"/>
    <limit effort="300" lower="-2.967" upper="2.967" velocity="2.0"/>
  </joint>

  <link name="upper_arm">
    <visual>
      <geometry>
        <cylinder length="0.4" radius="0.02"/>
      </geometry>
      <origin rpy="0 0 0" xyz="0 0 -0.2"/>
    </visual>
  </link>

  <joint name="elbow" type="revolute">
    <parent link="upper_arm"/>
    <child link="lower_arm"/>
    <origin rpy="0 0 0" xyz="0 0 -0.4"/>
    <axis xyz="0 1 0"/>
    <limit effort="300" lower="-2.967" upper="2.967" velocity="2.0"/>
  </joint>

  <link name="lower_arm">
    <visual>
      <geometry>
        <cylinder length="0.4" radius="0.02"/>
      </geometry>
      <origin rpy="0 0 0" xyz="0 0 -0.2"/>
    </visual>
  </link>

  <joint name="wrist" type="revolute">
    <parent link="lower_arm"/>
    <child link="hand"/>
    <origin rpy="0 0 0" xyz="0 0 -0.4"/>
    <axis xyz="0 1 0"/>
    <limit effort="100" lower="-1.57" upper="1.57" velocity="1.0"/>
  </joint>

  <link name="hand">
    <visual>
      <geometry>
        <box size="0.1 0.1 0.1"/>
      </geometry>
    </visual>
  </link>
</robot>
